{"id": 1, "step": 1, "input": "What is the capital of France?", "output": "\u001b[1;31mGive Feedback / Get Help: https://github.com/BerriAI/litellm/issues/new\u001b[0m\nLiteLLM.Info: If you need to debug this error, use `litellm.set_verbose=True'.\n\nError: AuthenticationError: OpenAIException - Traceback (most recent call last):\n  File \"/Users/griffin/.pyenv/versions/3.11.4/lib/python3.11/site-packages/litellm/llms/openai.py\", line 736, in completion\n    raise e\n  File \"/Users/griffin/.pyenv/versions/3.11.4/lib/python3.11/site-packages/litellm/llms/openai.py\", line 673, in completion\n    openai_client = self._get_openai_client(\n                    ^^^^^^^^^^^^^^^^^^^^^^^^\n  File \"/Users/griffin/.pyenv/versions/3.11.4/lib/python3.11/site-packages/litellm/llms/openai.py\", line 550, in _get_openai_client\n    _new_client = openai(\n                  ^^^^^^^\n  File \"/Users/griffin/.pyenv/versions/3.11.4/lib/python3.11/site-packages/openai/_client.py\", line 110, in __init__\n    raise openaiError(\nopenai.openaiError: The api_key client option must be set either by passing api_key to the client or by setting the OPENAI_API_KEY environment variable", "score": 0.0, "errors": ["model: Script failed with code 1: ", "scorer: Script failed with code 1: "]}
{"id": 2, "step": 1, "input": "What is 2 + 2?", "output": "\u001b[1;31mGive Feedback / Get Help: https://github.com/BerriAI/litellm/issues/new\u001b[0m\nLiteLLM.Info: If you need to debug this error, use `litellm.set_verbose=True'.\n\nError: AuthenticationError: OpenAIException - Traceback (most recent call last):\n  File \"/Users/griffin/.pyenv/versions/3.11.4/lib/python3.11/site-packages/litellm/llms/openai.py\", line 736, in completion\n    raise e\n  File \"/Users/griffin/.pyenv/versions/3.11.4/lib/python3.11/site-packages/litellm/llms/openai.py\", line 673, in completion\n    openai_client = self._get_openai_client(\n                    ^^^^^^^^^^^^^^^^^^^^^^^^\n  File \"/Users/griffin/.pyenv/versions/3.11.4/lib/python3.11/site-packages/litellm/llms/openai.py\", line 550, in _get_openai_client\n    _new_client = openai(\n                  ^^^^^^^\n  File \"/Users/griffin/.pyenv/versions/3.11.4/lib/python3.11/site-packages/openai/_client.py\", line 110, in __init__\n    raise openaiError(\nopenai.openaiError: The api_key client option must be set either by passing api_key to the client or by setting the OPENAI_API_KEY environment variable", "score": 0.0, "errors": ["model: Script failed with code 1: ", "scorer: Script failed with code 1: "]}
